Workbook
Name Q_郵便番号住所: #REF!
Name Q_郵便番号住所: #REF!
Name Q_郵便番号住所: #REF!
Name 阿寒郡: #REF!
Name 阿寒郡: #REF!
Name 阿寒郡: #REF!
Name 愛知県: #REF!
Name 愛知県: #REF!
Name 愛知県: #REF!
Name 愛媛県: #REF!
Name 愛媛県: #REF!
Name 旭川市: #REF!
Name 旭川市: #REF!
Name 芦別市: #REF!
Name 芦別市: #REF!
Name 虻田郡: #REF!
Name 虻田郡: #REF!
Name 伊達市: #REF!
Name 伊達市: #REF!
Name 磯谷郡: #REF!
Name 磯谷郡: #REF!
Name 茨城県: #REF!
Name 茨城県: #REF!
Name 雨竜郡: #REF!
Name 雨竜郡: #REF!
Name 浦河郡: #REF!
Name 浦河郡: #REF!
Name 奥尻郡: #REF!
Name 奥尻郡: #REF!
Name 岡山県: #REF!
Name 岡山県: #REF!
Name 沖縄: #REF!
Name 沖縄: #REF!
Name 沖縄県: #REF!
Name 沖縄県: #REF!
Name 歌志内市: #REF!
Name 歌志内市: #REF!
Name 河西郡: #REF!
Name 河西郡: #REF!
Name 河東郡: #REF!
Name 河東郡: #REF!
Name 樺戸郡: #REF!
Name 樺戸郡: #REF!
Name 茅部郡: #REF!
Name 茅部郡: #REF!
Name 刈田郡: #REF!
Name 刈田郡: #REF!
Name 岩見沢市: #REF!
Name 岩見沢市: #REF!
Name 岩手県: #REF!
Name 岩手県: #REF!
Name 岩内郡: #REF!
Name 岩内郡: #REF!
Name 岐阜県: #REF!
Name 岐阜県: #REF!
Name 亀田郡: #REF!
Name 亀田郡: #REF!
Name 久遠郡: #REF!
Name 久遠郡: #REF!
Name 宮崎県: #REF!

Sheet 本紙
C1: 【様式１】サービス申込書
C5: 本様式はスマート光ビジネスWi-Fiハイエンドプランの各種注文にて利用する申込書です。
C6: 注文内容を選択し、内容に応じた別紙に必要事項を記載・送付してください。
C7: なお、AP毎のSSID設定など、詳細設定を希望する場合には別途"【様式２】詳細設定申込書"を合わせて記載・送付してください
C9: 注文内容 | S9: 新規・追加・減少・廃止申込(月額支払い型)
C12: 詳細設定/初期キッティング希望 | S12: 希望する(本申込書に加えて【様式２】を記載・送付してください)
C16: 注文内容 | S16: 記入が必要な別紙
C19: 新規・追加・減少・廃止申込(月額支払い型) | S19: =IF(S9="新規・追加・減少・廃止・タイプ変更申込",HYPERLINK('別紙①-1_月額支払い型申込書'!A1,"別紙①-1"),"別紙①-1") -> 別紙①-1
S22: 別紙②
C25: 新規・追加・減少・廃止申込（補助金対応型申込） | S25: 別紙①-2
S28: 別紙②
C31: 移転・契約情報変更・設定変更申込 | S31: 別紙③

Sheet 別紙①-1_月額支払い型申込書
A1: =AZ5 -> Ver2.7(2023.6.12～) | B1: スマート光ビジネスWi-Fiハイエンドプラン（月額支払い型） 申込書
B5: 事業者名 | I5: 西日本電信電話株式会社 | Y5: 事業者識別コード | AF5: XB5 | AZ5: Ver2.7(2023.6.12～)
B6: 私は「スマート光ビジネスWi-Fi利用規約（http://flets-w.com/solution/wi-fi_service/）」を確認・承諾のうえ、サービス契約（新規、変更、解約）を申し込みます。
B7: 申込日 | H7: 西暦 | J7: 2023 | N7: 年 | O7: 9 | S7: 月 | T7: 8 | X7: 日 | AJ7: OEM事業者管理ID | AO7: ="CAF"&M23&N23&O23&P23&Q23&R23&S23&T23&U23&V23&"WSO"&LEFT(I11,6)&[1]Sheet1!A3&[1]Sheet1!B3 -> CAF5231164323WSO4500000920
B8: ご契約者様名 （法人名） | H8: フリガナ | K8: カブシキガイシャハットリフォトスタジオ | AU8: 印
H9: 株式会社ハットリフォトスタジオ
B11: ご契約者様住所 | H11: 〒 | I11: 4500003 | Q11: フリガナ | T11: ナゴヤシナカムラクメイエキミナミ3-14-22 | BA11: ←フレッツのオプションサービスのため、回線名義と同じとします。
H12: 都道府県 | K12: 愛知県 | Q12: 市区町村 番地 | T12: 名古屋市中村区名駅南3-14-22 | BA12: ※個人名義の場合、「部課名」に会社名や団体名をご記載し、個人利用でないことを明確化してください。
H14: ■ | J14: 島嶼部の場合はチェック | Q14: （建物名）
B15: 開通案内送付先住所 | H15: ■ | K15: ご契約者様住所と同一の場合はチェック
H16: 〒 | Q16: フリガナ
H17: 都道府県 | Q17: 市区町村 番地
H19: □ | J19: 島嶼部の場合はチェック | Q19: （建物名）
B20: 開通案内送付先 会社・部署名等 | H20: 株式会社ハットリフォトスタジオ | W20: 担当者名 | AC20: フリガナ | AF20: ハットリ カズナリ
AC21: 服部 一成
B23: 契約アクセス回線 | H23: CAF | M23: 5 | N23: 2 | O23: 3 | P23: 1 | Q23: 1 | R23: 6 | S23: 4 | T23: 3 | U23: 2 | V23: 3 | W23: 東日本エリアや他社回線拠点の場合は、お客様本社等課金先のものを記載する。
B24: ご契約者様連絡先 | C24: 担当部署名 | H24: 株式会社ハットリフォトスタジオ | W24: 担当者名 | AC24: フリガナ | AF24: ハットリ カズナリ
AC25: 服部 一成
C27: 電話番号1 | W27: ご契約者様サポートは電話とメールで行います。 確実に連絡可能な電話番号とメールアドレスをご記入ください。 申込受付完了後、記載のメールアドレスまで連絡先の確認メールを送付いたします。
H28: （ | I28: 052 | L28: ） | M28: 561 | Q28: － | R28: 1667
C30: 電話番号2 (緊急時)
H31: （ | I31: 052 | L31: ） | M31: 561 | Q31: － | R31: 1667
C33: メールアドレス | H33: k.h | AA33: ＠ | AB33: hattori-studio.com
B35: ■必須記載欄
B36: 契約内容 | I36: ■ | J36: 新規 | L36: □ | M36: 追加 | P36: □ | Q36: 減少 | T36: □ | U36: 廃止 | AE36: APID (AP減少・廃止時のみ)
B37: 契約ID （新規申込以外記入） | H37: WOW
B38: お申し込みプラン・ 台数 | H38: □ | L38: ハイエンドプラン | V38: ： | Y38: 台 | AD38: ■ | AH38: ハイエンド6プラン | AR38: ： | AS38: 1 | AU38: 台
H39: ※一つの申込書で月額支払い型、お買い上げ型の両方を同時に申込は出来ません ※一つの申込書でハイエンドプラン、ハイエンド6プランの両方を同時に申込は出来ません
B40: AP配送希望日 | H40: 西暦 | J40: 2023 | N40: 年 | O40: 9 | S40: 月 | T40: 20 | X40: 日 | Y40: ※希望日の設定について必ずご一読ください ■ 初期キッティングを申し込まれない場合 ・AP配送希望日は、申込受領日の翌日から起算し、4営業日以降で記載してください。 ※北海道、九州へのAP配送は、＋1営業日必要です。 ※全県の島嶼部への配送は、＋3営業日必要です。 ※AP配送日は、申込日から最大3ヶ月先まで指定可能です。 ※土日祝は指定できません。 ・AP開通希望日は、AP配送希望日の翌々営業日以降で記載してください。 ■ 初期キッティングを申し込まれる場合 ・AP配送希望日は、申込受領日の翌日から起算し、5営業日以降で記載してください。 なお、AP配送希望日はキッティングセンタへの配送日であり設置場所配送日ではありません。 ・AP開通希望日は、AP配送希望日の翌日から起算し、設置場所が西日本エリアの場合は５営業日以降、 東日本エリアの場合は9営業日以降を記載してください。 設置場所へのAP配送日はAP開通希望日の前営業日になります。 ■ AP廃止・減少希望日は、14時までを申込日当日として3営業日以降で記載してください。 遡及はできません。
B41: AP開通希望日 | H41: 西暦 | J41: 2023 | N41: 年 | O41: 9 | S41: 月 | T41: 22 | X41: 日
B42: AP廃止・ 減少希望日 | H42: 西暦 | N42: 年 | S42: 月 | X42: 日
B43: 機器設置場所住所 | H43: ■ | K43: ご契約者様住所と同一の場合はチェック
H44: 〒 | Q44: フリガナ
H45: 都道府県 | Q45: 市区町村 番地
H47: □ | J47: 島嶼部の場合はチェック | Q47: （建物名）
B48: 機器配送場所住所 ※初期キッティング利用時は欄外右記の住所を記載 | H48: □ | K48: ご契約者様住所と同一の場合はチェック | BC48: 初期キッティング利用時は以下を機器送付先としてください。
H49: 〒 | L49: - | Q49: フリガナ | BC49: 〒 | BD49: 460 | BG49: - | BH49: 0008 | BL49: フリガナ | BO49: ナゴヤシナカクサカエ5-12-13
H50: 都道府県 | K50: 愛知県 | Q50: 市区町村 | T50: 名古屋市中区新栄町 | AB50: 住所 (続き) | AE50: 2-10 NTT栄ビル西館1F | BC50: 都道府県 | BF50: 愛知県 | BL50: 市区町村 | BO50: 名古屋市中区 | BW50: 住所 (続き) | BZ50: 栄 5-12-13
H52: □ | J52: 島嶼部の場合はチェック | Q52: （建物名） | BC52: □ | BE52: 島嶼部の場合はチェック | BL52: （建物名） | BO52: ＮＴＴ中ビル西館1Ｆ
H53: お届け先 会社・部署名等 | N53: NTT西日本ビジネスフロント（株） | AC53: 受取人名 | AI53: フリガナ | AL53: イシガキ アキノブ | BC53: お届け先 会社・部署名等 | BI53: NTTBS カスタマーサクセス部 | BX53: 受取人名 | CD53: フリガナ | CG53: マネージドオペレーションタントウ
...

Sheet 別紙①-2_お客様お買い上げ型申込書
A1: =AZ5 -> Ver2.7(2023.6.12～) | B1: スマート光ビジネスWi-Fiハイエンドプラン（お買い上げ型） 申込書
B5: 事業者名 | I5: 西日本電信電話株式会社 | Y5: 事業者識別コード | AF5: XB5 | AZ5: Ver2.7(2023.6.12～)
B6: 私は「スマート光ビジネスWi-Fi利用規約（http://flets-w.com/solution/wi-fi_service/）」「重要事項説明書」「ライセンス使用許諾書」を確認・承諾のうえ、サービス契約（新規、変更、解約）を申し込みます。
B7: 申込日 | H7: 西暦 | N7: 年 | S7: 月 | X7: 日 | AJ7: OEM事業者管理ID | AO7: ="CAF"&M23&N23&O23&P23&Q23&R23&S23&T23&U23&V23&"WSO"&LEFT(I11,6)&[1]Sheet1!C3&[1]Sheet1!D3 -> CAFWSO0000
B8: ご契約者様名 （法人名） | H8: フリガナ | AU8: 印
B11: ご契約者様住所 | H11: 〒 | Q11: フリガナ | BA11: ←フレッツのオプションサービスのため、回線名義と同じとします。
H12: 都道府県 | Q12: 市区町村 番地 | BA12: ※個人名義の場合、「部課名」に会社名や団体名をご記載し、個人利用でないことを明確化してください。
H14: □ | J14: 島嶼部の場合はチェック | Q14: （建物名）
B15: 開通案内送付先住所 | H15: □ | K15: ご契約者様住所と同一の場合はチェック
H16: 〒 | Q16: フリガナ
H17: 都道府県 | Q17: 市区町村 番地
H19: □ | J19: 島嶼部の場合はチェック | Q19: （建物名）
B20: 開通案内送付先 会社・部署名等 | W20: 担当者名 | AC20: フリガナ
B23: 契約アクセス回線 | H23: CAF | W23: 東日本エリアや他社回線拠点の場合は、お客様本社等課金先のものを記載する。
B24: ご契約者様連絡先 | C24: 担当部署名 | W24: 担当者名 | AC24: フリガナ
C27: 電話番号1 | W27: ご契約者様サポートは電話とメールで行います。 確実に連絡可能な電話番号とメールアドレスをご記入ください。 申込受付完了後、記載のメールアドレスまで連絡先の確認メールを送付いたします。
H28: （ | L28: ） | Q28: －
C30: 電話番号2 (緊急時)
H31: （ | L31: ） | Q31: －
C33: メールアドレス | AA33: ＠
B35: ■必須記載欄
B36: 契約内容 | I36: □ | J36: 新規 | L36: □ | M36: 追加 | P36: □ | Q36: 減少 | T36: □ | U36: 廃止 | AE36: APID (AP減少・廃止時のみ)
B37: 契約ID （新規申込以外記入） | H37: WOW
B38: お申し込みプラン・ 台数 | H38: □ | L38: ハイエンドプラン | V38: ： | Y38: 台 | AD38: ※一つの申込書で月額支払い型、お買い上げ型の両方を同時に申込は出来ません
AD39: ※お買い上げ型のハイエンドプランの対応機器はハイエンド6プランと同じです
B40: AP配送希望日 | H40: 西暦 | N40: 年 | S40: 月 | X40: 日 | Y40: ※希望日の設定について必ずご一読ください ■ 初期キッティングを申し込まれない場合 ・AP配送希望日は、申込受領日の翌日から起算し、4営業日以降で記載してください。 ※北海道、九州へのAP配送は、＋1営業日必要です。 ※全県の島嶼部への配送は、＋3営業日必要です。 ※AP配送日は、申込日から最大3ヶ月先まで指定可能です。 ※土日祝は指定できません。 ・AP開通希望日は、AP配送希望日の翌々営業日以降で記載してください。 ■ 初期キッティングを申し込まれる場合 ・AP配送希望日は、申込受領日の翌日から起算し、5営業日以降で記載してください。 なお、AP配送希望日はキッティングセンタへの配送日であり設置場所配送日ではありません。 ・AP開通希望日は、AP配送希望日の翌日から起算し、設置場所が西日本エリアの場合は５営業日以降、 東日本エリアの場合は9営業日以降を記載してください。 設置場所へのAP配送日はAP開通希望日の前営業日になります。 ■ AP廃止・減少希望日は、14時までを申込日当日として3営業日以降で記載してください。 遡及はできません。
B41: AP開通希望日 | H41: 西暦 | N41: 年 | S41: 月 | X41: 日
B42: AP廃止・ 減少希望日 | H42: 西暦 | N42: 年 | S42: 月 | X42: 日
B43: 機器設置場所住所 | H43: □ | K43: ご契約者様住所と同一の場合はチェック
H44: 〒 | Q44: フリガナ
H45: 都道府県 | Q45: 市区町村 番地
H47: □ | J47: 島嶼部の場合はチェック | Q47: （建物名）
B48: 機器配送場所住所 ※初期キッティング利用時は欄外右記の住所を記載 | H48: □ | K48: ご契約者様住所と同一の場合はチェック | BY48: 初期キッティング利用時は以下を機器送付先としてください。
H49: 〒 | L49: - | Q49: フリガナ | BY49: 〒 | BZ49: 460 | CC49: - | CD49: 0008 | CH49: フリガナ | CK49: ナゴヤシナカクサカエ5-12-13
H50: 都道府県 | Q50: 市区町村 | AB50: 住所 (続き) | BY50: 都道府県 | CB50: 愛知県 | CH50: 市区町村 | CK50: 名古屋市中区 | CS50: 住所 (続き) | CV50: 栄 5-12-13
H52: □ | J52: 島嶼部の場合はチェック | Q52: （建物名） | BY52: □ | CA52: 島嶼部の場合はチェック | CH52: （建物名） | CK52: ＮＴＴ中ビル西館1Ｆ
H53: お届け先 会社・部署名等 | AC53: 受取人名 | AI53: フリガナ | BY53: お届け先 会社・部署名等 | CE53: NTTBS カスタマーサクセス部 | CT53: 受取人名 | CZ53: フリガナ | DC53: マネージドオペレーションタントウ
CZ54: マネージドオペレーション担当
H56: 電話番号1 | AC56: 電話番号2 | BY56: 電話番号1 | CT56: 電話番号2
N57: （ | R57: ） | W57: － | AI57: （ | AM57: ） | AR57: － | CE57: （ | CF57: 052 | CI57: ） | CJ57: 211 | CN57: － | CO57: 9102 | CZ57: （ | DD57: ） | DI57: －
...

Sheet 別紙②_Wi-Fi設定 
B1: 別紙②_Wi-Fi設定
B6: 同一設置場所のWi-Fiアクセスポイント装置は、原則、同一設定となります。
B8: ※AP毎に異なる設定を希望する場合は、本シート（別紙②）の代わりに"様式２詳細設定申込書"にご記入ください
B10: Wi-Fi設定
C14: SSID（ネットワーク名） | L14: ： | M14: Wi-Fiを識別するための名前です。スマートフォンでは「Wi-Fiネットワーク」の画面に表示されます。
M15: （パソコンでは「ワイヤレスネットワーク接続」の画面に表示されます。）
C16: パスワード（暗号化キー） | L16: ： | M16: SSID(ネットワーク名）に接続するためのパスワードです。外部の人が推測できないパスワードを推奨します。
B18: Wi-Fi設定①
F19: フリガナ | H19: エイチ エー ティー ティー オー アール アイ ハイフン ピー エイチ オー ティー オー ハイフン エス ティー
B20: SSID （ネットワーク名） | H20: hattori-photo-st
H21: 半角32文字以内。英字（大文字、小文字）、数字、記号（-（ハイフン）、@（アットマーク）、＃（ハッシュマーク）、_（アンダーバー）、．（ピリオド））を使用できます。 ※指定の文字以外では設定できません。
F22: フリガナ | H22: エイチ エー ティー ティー オー アール アイ イチ ロク ロク ナナ
B23: パスワード （暗号化キー） | H23: hattori1667
H24: 半角8文字以上。英字（大文字、小文字）、数字、記号（-（ハイフン）、@（アットマーク）、＃（ハッシュマーク）、_（アンダーバー）、．（ピリオド））を使用できます。 2種類以上の文字を使用してください。
B26: Wi-Fi設定②
F27: フリガナ
B28: SSID （ネットワーク名）
H29: 半角32文字以内。英字（大文字、小文字）、数字、記号（-（ハイフン）、@（アットマーク）、＃（ハッシュマーク）、_（アンダーバー）、．（ピリオド））を使用できます。 ※指定の文字以外では設定できません。
F30: フリガナ
B31: パスワード （暗号化キー）
H32: 半角8文字以上。英字（大文字、小文字）、数字、記号（-（ハイフン）、@（アットマーク）、＃（ハッシュマーク）、_（アンダーバー）、．（ピリオド））を使用できます。
C33: ※SSIDを3以上設定する場合、本シートをコピーして記入してください。
B35: 来訪者向けWi-FiインターネットのWi-Fi設定
F37: フリガナ | H37: エイチ エー ティー ティー オー アール アイ ハイフン ピー エイチ オー ティー オー ハイフン ジー ユー イー エス ティー
B38: 来訪者向け SSID 1 （ネットワーク名） | H38: hattori-photo-guest
H39: 半角32文字以内。英字（大文字、小文字）、数字、記号（-（ハイフン）、@（アットマーク）、＃（ハッシュマーク）、_（アンダーバー）、．（ピリオド））を使用できます。 ※指定の文字以外では設定できません。
F40: フリガナ | H40: エス ﾃｨｰ ハイフン ｼﾞｰ ユー イー エス ティー イチ ロク ロク ハチ
B41: 来訪者向け パスワード1 （暗号化キー） | H41: st-guest-1668
H42: 半角8文字以上。英字（大文字、小文字）、数字、記号（-（ハイフン）、@（アットマーク）、＃（ハッシュマーク）、_（アンダーバー）、．（ピリオド））を使用できます。
F44: フリガナ
B45: 来訪者向け SSID2 （ネットワーク名）
H46: 半角32文字以内。英字（大文字、小文字）、数字、記号（-（ハイフン）、@（アットマーク）、＃（ハッシュマーク）、_（アンダーバー）、．（ピリオド））を使用できます。
F47: フリガナ
B48: 来訪者向け パスワード2 （暗号化キー）
H49: 半角8文字以上。英字（大文字、小文字）、数字、記号（-（ハイフン）、@（アットマーク）、＃（ハッシュマーク）、_（アンダーバー）、．（ピリオド））を使用できます。
C50: ※SSIDを3以上設定する場合、本シートをコピーして記入してください。
B52: Facebook Wi-Fiの設定
B54: 利用有無 | H54: □ | J54: 利用する
B55: 設定するSSID | H55: □ | J55: 来訪者向けSSID 1 | Q55: □ | S55: 来訪者向けSSID 2
B56: アカウント名
...

Sheet 別紙③_移転・契約情報変更・設定変更申込
B1: 別紙③_移転・契約情報変更時利用
B5: 事業者名 | H5: 西日本電信電話株式会社 | Y5: 事業者識別コード | AF5: XB5
B6: 申込日 | H6: 西暦 | N6: 年 | S6: 月 | X6: 日 | AJ6: OEM事業者管理ID | AO6: ="CAF"&M23&N23&O23&P23&Q23&R23&S23&T23&U23&V23&"WSO"&LEFT(I15,6)&[1]Sheet1!E3&[1]Sheet1!F3 -> CAFWSO0000
B8: ■必須記載欄
B9: 契約ID
B10: 【現登録情報】 ご契約者様名 （法人名） | H10: 契約者名/部署名
H12: 氏名 | M12: フリガナ | AE12: 日中の連絡先 電話番号
AK13: （ | AO13: ） | AS13: －
B15: 【現登録情報】 ご契約者様住所 | H15: 〒 | Q15: フリガナ
H16: 都道府県 | Q16: 市区町村 番地
Q18: （建物名）
B19: 【現登録情報】 設置場所住所 | H19: 〒 | Q19: フリガナ
H20: 都道府県 | Q20: 市区町村 番地
Q22: （建物名）
B23: 【現登録情報】 契約アクセス回線 | H23: CAF
B25: 申込内容 | H25: □ | I25: 契約者名義の変更 | O25: □ | P25: 契約者住所の変更 | W25: □ | X25: 設置場所住所の変更（移転日）
B26: 【変更後】 ご契約者様名 （法人名） | H26: フリガナ
B29: 【変更後】 ご契約者様住所 | H29: 〒 | Q29: フリガナ
H30: 都道府県 | Q30: 市区町村 番地
Q32: （建物名）
B33: 【変更後】 設置場所住所 | H33: 〒 | Q33: フリガナ
H34: 都道府県 | Q34: 市区町村 番地
Q36: （建物名）
B37: 【変更後】 契約アクセス回線 | H37: CAF
B38: 備考

Sheet 解約金計算ツール
A1: LAN給電オプション違約金計算ツール | P1: =IF(AND(OR('別紙①-1_月額支払い型申込書'!J42="",'別紙①-1_月額支払い型申込書'!O42="",'別紙①-1_月額支払い型申込書'!T42=""),OR('別紙①-2_お客様お買い上げ型申込書'!J42="",'別紙①-2_お客様お買い上げ型申込書'!O42="",'別紙①-2_お客様お買い上げ型申込書'!T42="")),"",IF(COUNTIF(B6:B34,"お買い上げ型")>=1,DATE('別紙①-2_お客様お買い上げ型申込書'!J42,'別紙①-2_お客様お買い上げ型申込書'!O42,'別紙①-2_お客様お買い上げ型申込書'!T42),DATE('別紙①-1_月額支払い型申込書'!J42,'別紙①-1_月額支払い型申込書'!O42,'別紙①-1_月額支払い型申込書'!T42)))
A2: ※APの解約金は計算されません | G2: PoE廃止・減少希望日 | L2: =IF(AND(OR('別紙①-1_月額支払い型申込書'!J64="",'別紙①-1_月額支払い型申込書'!O64="",'別紙①-1_月額支払い型申込書'!T64=""),OR('別紙①-2_お客様お買い上げ型申込書'!J64="",'別紙①-2_お客様お買い上げ型申込書'!O64="",'別紙①-2_お客様お買い上げ型申込書'!T64="")),"",IF(P2=3,DATE('別紙①-1_月額支払い型申込書'!J64,'別紙①-1_月額支払い型申込書'!O64,'別紙①-1_月額支払い型申込書'!T64),DATE('別紙①-2_お客様お買い上げ型申込書'!J64,'別紙①-2_お客様お買い上げ型申込書'!O64,'別紙①-2_お客様お買い上げ型申込書'!T64))) | P2: =COUNTIFS('別紙①-1_月額支払い型申込書'!J64,"<>")+COUNTIFS('別紙①-1_月額支払い型申込書'!O64,"<>")+COUNTIFS('別紙①-1_月額支払い型申込書'!T64,"<>") -> 0 | Q2: =COUNTIFS('別紙①-2_お客様お買い上げ型申込書'!J64,"<>")+COUNTIFS('別紙①-2_お客様お買い上げ型申込書'!O64,"<>")+COUNTIFS('別紙①-2_お客様お買い上げ型申込書'!T64,"<>") -> 0
G4: 違約金合計（税込） | K4: =SUM(N7,N10,N13,N16,N19,N22,N25,N28,N31,N34) -> 0 | U4: =DATEDIF(Z7,U7,"m") -> #VALUE! | AB4: =DAY(Z7)-DAY(U7) -> #VALUE!
P5: 利用開始 | U5: 満了 | Z5: 解約日 | AE5: 判定 | AF5: 残期間 | AJ5: 違約金 | AX5: ※先に「別紙①-1_月額支払い型申込書」か「別紙①-2_お客様お買い上げ型申込書」の
A6: 1 | B6: プラン | E6: 利用開始日 | L6: 台数 | N6: 違約金 | P6: 利用開始 | Q6: 歴日数 | R6: EOM | S6: 日割数 | T6: 満フラグ | U6: 満了日 | V6: 歴日数 | W6: EOM | X6: 日割数 | Y6: 満フラグ | Z6: 解約日 | AA6: 歴日数 | AB6: EOM | AC6: 日割数 | AD6: 満フラグ | AE6: 違約金有無 | AF6: 残期間(年) | AG6: 残期間(月) | AH6: 残期間(日) | AI6: 残期間 | AJ6: 解約金日割 | AK6: 満額 | AL6: 違約金計 | AM6: 違約金表示 | AO6: プラン | AQ6: 年 | AR6: 月 | AS6: 日 | AT6: AP | AU6: プラン | AX6: 「PoE廃止・減少希望日」を入力してください。未入力時は計算されません。
C7: =IF(B7="","",VLOOKUP(B7,$AO$7:$AP$12,2,)) | F7: 年 | H7: 月 | J7: 日 | N7: =IF(OR(L7="",AM7=""),"",AM7*L7) | P7: =IF(OR(E7="",G7="",I7=""),"",DATE(E7,G7,I7)) | Q7: =IF(P7="","",IF(OR(G7=1,G7=3,G7=5,G7=7,G7=8,G7=10,G7=12),31,IF(OR(G7=4,G7=6,G7=9,G7=11),30,IF(AND(E7=2020,G7=2),29,IF(AND(E7=2024,G7=2),29,28))))) | R7: =IF(P7="","",EOMONTH(P7,0)) | S7: =IF(P7="","",R7-P7+1) | T7: =IF(P7="","",IF(I7=1,1,0)) | U7: =IF(P7="","",IF(B7="LAN給電5年",DATE(YEAR(P7)+5,MONTH(P7),DAY(P7)-1),DATE(YEAR(P7)+2,MONTH(P7),DAY(P7)-1))) | V7: =IF(P7="","",IF(OR(MONTH(U7)=1,MONTH(U7)=3,MONTH(U7)=5,MONTH(U7)=7,MONTH(U7)=8,MONTH(U7)=10,MONTH(U7)=12),31,IF(OR(MONTH(U7)=4,MONTH(U7)=6,MONTH(U7)=9,MONTH(U7)=11),30,IF(AND(YEAR(U7)=2020,MONTH(U7)=2),29,IF(AND(YEAR(U7)=2024,MONTH(U7)=2),29,28))))) | W7: =IF(P7="","",EOMONTH(U7,-1)+1) | X7: =IF(P7="","",U7-W7+1) | Y7: =IF(P7="","",IF(U7=EOMONTH(U7,0),1,0)) | Z7: =IF(P7="","",IF($L$2="","",$L$2)) | AA7: =IF(P7="","",IF(OR(MONTH(Z7)=1,MONTH(Z7)=3,MONTH(Z7)=5,MONTH(Z7)=7,MONTH(Z7)=8,MONTH(Z7)=10,MONTH(Z7)=12),31,IF(OR(MONTH(Z7)=4,MONTH(Z7)=6,MONTH(Z7)=9,MONTH(Z7)=11),30,IF(AND(YEAR(Z7)=2020,MONTH(Z7)=2),29,IF(AND(YEAR(Z7)=2024,MONTH(Z7)=2),29,28))))) | AB7: =IF(P7="","",IF($L$2="","",EOMONTH(Z7,0))) | AC7: =IF(P7="","",IF($L$2="","",AB7-Z7)+1) | AD7: =IF(P7="","",IF(DAY(Z7)=1,1,0)) | AE7: =IF(P7="","",IF(B7="お買い上げ型","無",IF(U7<Z7,"無","有"))) | AF7: =IF(P7="","",IF(AE7="無","",DATEDIF(Z7,U7,"y"))) | AG7: =IF(P7="","",IF(AE7="無","",IF(YEAR(U7)&MONTH(U7)=YEAR(Z7)&MONTH(Z7),0,DATEDIF(Z7,U7,"m")-(12*AF7)+Y7+AD7-IF((DAY(Z7)-DAY(U7))<=0,1,0)))) | AH7: =IF(P7="","",IF(AE7="無","",IF(YEAR(U7)&MONTH(U7)=YEAR(Z7)&MONTH(Z7),AC7,IF(V7=X7,0,X7)+IF(AA7=AC7,0,AC7)))) | AI7: =IF(P7="","",AF7&"年"&AG7&"か月"&AH7&"日") | AJ7: =IF(P7="","",IF(AE7="無",0,IF(YEAR(U7)&MONTH(U7)=YEAR(Z7)&MONTH(Z7),ROUNDDOWN(C7*AH7/V7,0),ROUNDDOWN(C7*IF(V7=X7,0,X7)/V7,0)+ROUNDDOWN(C7*IF(AA7=AC7,0,AC7)/AA7,0)))) | AK7: =IF(P7="","",IF(AE7="無",0,ROUNDDOWN((C7*AG7)+(C7*AF7*12),0))) | AL7: =IF(P7="","",AJ7+AK7) | AM7: =IF(P7="","",IF(COUNTIF(B7,"LAN*")=1,AJ7+AK7,IF(AJ7+AK7>=10000,10000,AJ7+AK7))) | AO7: LAN給電2年 | AP7: 880 | AQ7: 2017 | AR7: 1 | AS7: 1 | AT7: 1 | AY7: ←この色のセルのみ入力してください。他は自動反映します。
AO8: LAN給電5年 | AP8: 440 | AQ8: 2018 | AR8: 2 | AS8: 2 | AT8: 2 | AX8: ※同一プランを複数契約している場合でも、利用開始日が異なる場合は別々に入力が必要です。
A9: 2 | B9: プラン | E9: 利用開始日 | L9: 台数 | N9: 違約金 | P9: 利用開始 | Q9: 歴日数 | R9: EOM | S9: 日割数 | T9: 満フラグ | U9: 満了日 | V9: 歴日数 | W9: EOM | X9: 日割数 | Y9: 満フラグ | Z9: 解約日 | AA9: 歴日数 | AB9: EOM | AC9: 日割数 | AD9: 満フラグ | AE9: 違約金有無 | AF9: 残期間(年) | AG9: 残期間(月) | AH9: 残期間(日) | AI9: 残期間 | AJ9: 解約金日割 | AK9: 満額 | AL9: 違約金計 | AM9: 違約金表示 | AQ9: 2019 | AR9: 3 | AS9: 3 | AT9: 3
C10: =IF(B10="","",VLOOKUP(B10,$AO$7:$AP$12,2,)) | F10: 年 | H10: 月 | J10: 日 | N10: =IF(OR(L10="",AM10=""),"",AM10*L10) | P10: =IF(OR(E10="",G10="",I10=""),"",DATE(E10,G10,I10)) | Q10: =IF(P10="","",IF(OR(G10=1,G10=3,G10=5,G10=7,G10=8,G10=10,G10=12),31,IF(OR(G10=4,G10=6,G10=9,G10=11),30,IF(AND(E10=2020,G10=2),29,IF(AND(E10=2024,G10=2),29,28))))) | R10: =IF(P10="","",EOMONTH(P10,0)) | S10: =IF(P10="","",R10-P10+1) | T10: =IF(P10="","",IF(I10=1,1,0)) | U10: =IF(P10="","",IF(B10="LAN給電5年",DATE(YEAR(P10)+5,MONTH(P10),DAY(P10)-1),DATE(YEAR(P10)+2,MONTH(P10),DAY(P10)-1))) | V10: =IF(P10="","",IF(OR(MONTH(U10)=1,MONTH(U10)=3,MONTH(U10)=5,MONTH(U10)=7,MONTH(U10)=8,MONTH(U10)=10,MONTH(U10)=12),31,IF(OR(MONTH(U10)=4,MONTH(U10)=6,MONTH(U10)=9,MONTH(U10)=11),30,IF(AND(YEAR(U10)=2020,MONTH(U10)=2),29,IF(AND(YEAR(U10)=2024,MONTH(U10)=2),29,28))))) | W10: =IF(P10="","",EOMONTH(U10,-1)+1) | X10: =IF(P10="","",U10-W10+1) | Y10: =IF(P10="","",IF(U10=EOMONTH(U10,0),1,0)) | Z10: =IF(P10="","",IF($L$2="","",$L$2)) | AA10: =IF(P10="","",IF(OR(MONTH(Z10)=1,MONTH(Z10)=3,MONTH(Z10)=5,MONTH(Z10)=7,MONTH(Z10)=8,MONTH(Z10)=10,MONTH(Z10)=12),31,IF(OR(MONTH(Z10)=4,MONTH(Z10)=6,MONTH(Z10)=9,MONTH(Z10)=11),30,IF(AND(YEAR(Z10)=2020,MONTH(Z10)=2),29,IF(AND(YEAR(Z10)=2024,MONTH(Z10)=2),29,28))))) | AB10: =IF(P10="","",IF($L$2="","",EOMONTH(Z10,0))) | AC10: =IF(P10="","",IF($L$2="","",AB10-Z10)+1) | AD10: =IF(P10="","",IF(DAY(Z10)=1,1,0)) | AE10: =IF(P10="","",IF(B10="お買い上げ型","無",IF(U10<Z10,"無","有"))) | AF10: =IF(P10="","",IF(AE10="無","",DATEDIF(Z10,U10,"y"))) | AG10: =IF(P10="","",IF(AE10="無","",IF(YEAR(U10)&MONTH(U10)=YEAR(Z10)&MONTH(Z10),0,DATEDIF(Z10,U10,"m")-(12*AF10)+Y10+AD10-IF((DAY(Z10)-DAY(U10))<=0,1,0)))) | AH10: =IF(P10="","",IF(AE10="無","",IF(YEAR(U10)&MONTH(U10)=YEAR(Z10)&MONTH(Z10),AC10,IF(V10=X10,0,X10)+IF(AA10=AC10,0,AC10)))) | AI10: =IF(P10="","",AF10&"年"&AG10&"か月"&AH10&"日") | AJ10: =IF(P10="","",IF(AE10="無",0,IF(YEAR(U10)&MONTH(U10)=YEAR(Z10)&MONTH(Z10),ROUNDDOWN(C10*AH10/V10,0),ROUNDDOWN(C10*IF(V10=X10,0,X10)/V10,0)+ROUNDDOWN(C10*IF(AA10=AC10,0,AC10)/AA10,0)))) | AK10: =IF(P10="","",IF(AE10="無",0,ROUNDDOWN((C10*AG10)+(C10*AF10*12),0))) | AL10: =IF(P10="","",AJ10+AK10) | AM10: =IF(P10="","",IF(COUNTIF(B10,"LAN*")=1,AJ10+AK10,IF(AJ10+AK10>=10000,10000,AJ10+AK10))) | AQ10: 2020 | AR10: 4 | AS10: 4 | AT10: 4
AQ11: 2021 | AR11: 5 | AS11: 5 | AT11: 5
A12: 3 | B12: プラン | E12: 利用開始日 | L12: 台数 | N12: 違約金 | P12: 利用開始 | Q12: 歴日数 | R12: EOM | S12: 日割数 | T12: 満フラグ | U12: 満了日 | V12: 歴日数 | W12: EOM | X12: 日割数 | Y12: 満フラグ | Z12: 解約日 | AA12: 歴日数 | AB12: EOM | AC12: 日割数 | AD12: 満フラグ | AE12: 違約金有無 | AF12: 残期間(年) | AG12: 残期間(月) | AH12: 残期間(日) | AI12: 残期間 | AJ12: 解約金日割 | AK12: 満額 | AL12: 違約金計 | AM12: 違約金表示 | AQ12: 2022 | AR12: 6 | AS12: 6 | AT12: 6 | AX12: （例） | AY12: 契約プラン | AZ12: ・LAN給電オプション(5年タイプ)を2017/2/4から3台利用中
C13: =IF(B13="","",VLOOKUP(B13,$AO$7:$AP$12,2,)) | F13: 年 | H13: 月 | J13: 日 | N13: =IF(OR(L13="",AM13=""),"",AM13*L13) | P13: =IF(OR(E13="",G13="",I13=""),"",DATE(E13,G13,I13)) | Q13: =IF(P13="","",IF(OR(G13=1,G13=3,G13=5,G13=7,G13=8,G13=10,G13=12),31,IF(OR(G13=4,G13=6,G13=9,G13=11),30,IF(AND(E13=2020,G13=2),29,IF(AND(E13=2024,G13=2),29,28))))) | R13: =IF(P13="","",EOMONTH(P13,0)) | S13: =IF(P13="","",R13-P13+1) | T13: =IF(P13="","",IF(I13=1,1,0)) | U13: =IF(P13="","",IF(B13="LAN給電5年",DATE(YEAR(P13)+5,MONTH(P13),DAY(P13)-1),DATE(YEAR(P13)+2,MONTH(P13),DAY(P13)-1))) | V13: =IF(P13="","",IF(OR(MONTH(U13)=1,MONTH(U13)=3,MONTH(U13)=5,MONTH(U13)=7,MONTH(U13)=8,MONTH(U13)=10,MONTH(U13)=12),31,IF(OR(MONTH(U13)=4,MONTH(U13)=6,MONTH(U13)=9,MONTH(U13)=11),30,IF(AND(YEAR(U13)=2020,MONTH(U13)=2),29,IF(AND(YEAR(U13)=2024,MONTH(U13)=2),29,28))))) | W13: =IF(P13="","",EOMONTH(U13,-1)+1) | X13: =IF(P13="","",U13-W13+1) | Y13: =IF(P13="","",IF(U13=EOMONTH(U13,0),1,0)) | Z13: =IF(P13="","",IF($L$2="","",$L$2)) | AA13: =IF(P13="","",IF(OR(MONTH(Z13)=1,MONTH(Z13)=3,MONTH(Z13)=5,MONTH(Z13)=7,MONTH(Z13)=8,MONTH(Z13)=10,MONTH(Z13)=12),31,IF(OR(MONTH(Z13)=4,MONTH(Z13)=6,MONTH(Z13)=9,MONTH(Z13)=11),30,IF(AND(YEAR(Z13)=2020,MONTH(Z13)=2),29,IF(AND(YEAR(Z13)=2024,MONTH(Z13)=2),29,28))))) | AB13: =IF(P13="","",IF($L$2="","",EOMONTH(Z13,0))) | AC13: =IF(P13="","",IF($L$2="","",AB13-Z13)+1) | AD13: =IF(P13="","",IF(DAY(Z13)=1,1,0)) | AE13: =IF(P13="","",IF(B13="お買い上げ型","無",IF(U13<Z13,"無","有"))) | AF13: =IF(P13="","",IF(AE13="無","",DATEDIF(Z13,U13,"y"))) | AG13: =IF(P13="","",IF(AE13="無","",IF(YEAR(U13)&MONTH(U13)=YEAR(Z13)&MONTH(Z13),0,DATEDIF(Z13,U13,"m")-(12*AF13)+Y13+AD13-IF((DAY(Z13)-DAY(U13))<=0,1,0)))) | AH13: =IF(P13="","",IF(AE13="無","",IF(YEAR(U13)&MONTH(U13)=YEAR(Z13)&MONTH(Z13),AC13,IF(V13=X13,0,X13)+IF(AA13=AC13,0,AC13)))) | AI13: =IF(P13="","",AF13&"年"&AG13&"か月"&AH13&"日") | AJ13: =IF(P13="","",IF(AE13="無",0,IF(YEAR(U13)&MONTH(U13)=YEAR(Z13)&MONTH(Z13),ROUNDDOWN(C13*AH13/V13,0),ROUNDDOWN(C13*IF(V13=X13,0,X13)/V13,0)+ROUNDDOWN(C13*IF(AA13=AC13,0,AC13)/AA13,0)))) | AK13: =IF(P13="","",IF(AE13="無",0,ROUNDDOWN((C13*AG13)+(C13*AF13*12),0))) | AL13: =IF(P13="","",AJ13+AK13) | AM13: =IF(P13="","",IF(COUNTIF(B13,"LAN*")=1,AJ13+AK13,IF(AJ13+AK13>=10000,10000,AJ13+AK13))) | AQ13: 2023 | AR13: 7 | AS13: 7 | AT13: 7 | AZ13: ・LAN給電オプション(5年タイプ)を2017/5/1に2台追加して利用中
AQ14: 2024 | AR14: 8 | AS14: 8 | AT14: 8 | AZ14: ・LAN給電オプション(2年タイプ)を2020/2/4に1台追加して利用中
A15: 4 | B15: プラン | E15: 利用開始日 | L15: 台数 | N15: 違約金 | P15: 利用開始 | Q15: 歴日数 | R15: EOM | S15: 日割数 | T15: 満フラグ | U15: 満了日 | V15: 歴日数 | W15: EOM | X15: 日割数 | Y15: 満フラグ | Z15: 解約日 | AA15: 歴日数 | AB15: EOM | AC15: 日割数 | AD15: 満フラグ | AE15: 違約金有無 | AF15: 残期間(年) | AG15: 残期間(月) | AH15: 残期間(日) | AI15: 残期間 | AJ15: 解約金日割 | AK15: 満額 | AL15: 違約金計 | AM15: 違約金表示 | AQ15: 2025 | AR15: 9 | AS15: 9 | AT15: 9 | AY15: 2021/02/19にこれらを全廃止した場合、以下の通り入力が必要です。
C16: =IF(B16="","",VLOOKUP(B16,$AO$7:$AP$12,2,)) | F16: 年 | H16: 月 | J16: 日 | N16: =IF(OR(L16="",AM16=""),"",AM16*L16) | P16: =IF(OR(E16="",G16="",I16=""),"",DATE(E16,G16,I16)) | Q16: =IF(P16="","",IF(OR(G16=1,G16=3,G16=5,G16=7,G16=8,G16=10,G16=12),31,IF(OR(G16=4,G16=6,G16=9,G16=11),30,IF(AND(E16=2020,G16=2),29,IF(AND(E16=2024,G16=2),29,28))))) | R16: =IF(P16="","",EOMONTH(P16,0)) | S16: =IF(P16="","",R16-P16+1) | T16: =IF(P16="","",IF(I16=1,1,0)) | U16: =IF(P16="","",IF(B16="LAN給電5年",DATE(YEAR(P16)+5,MONTH(P16),DAY(P16)-1),DATE(YEAR(P16)+2,MONTH(P16),DAY(P16)-1))) | V16: =IF(P16="","",IF(OR(MONTH(U16)=1,MONTH(U16)=3,MONTH(U16)=5,MONTH(U16)=7,MONTH(U16)=8,MONTH(U16)=10,MONTH(U16)=12),31,IF(OR(MONTH(U16)=4,MONTH(U16)=6,MONTH(U16)=9,MONTH(U16)=11),30,IF(AND(YEAR(U16)=2020,MONTH(U16)=2),29,IF(AND(YEAR(U16)=2024,MONTH(U16)=2),29,28))))) | W16: =IF(P16="","",EOMONTH(U16,-1)+1) | X16: =IF(P16="","",U16-W16+1) | Y16: =IF(P16="","",IF(U16=EOMONTH(U16,0),1,0)) | Z16: =IF(P16="","",IF($L$2="","",$L$2)) | AA16: =IF(P16="","",IF(OR(MONTH(Z16)=1,MONTH(Z16)=3,MONTH(Z16)=5,MONTH(Z16)=7,MONTH(Z16)=8,MONTH(Z16)=10,MONTH(Z16)=12),31,IF(OR(MONTH(Z16)=4,MONTH(Z16)=6,MONTH(Z16)=9,MONTH(Z16)=11),30,IF(AND(YEAR(Z16)=2020,MONTH(Z16)=2),29,IF(AND(YEAR(Z16)=2024,MONTH(Z16)=2),29,28))))) | AB16: =IF(P16="","",IF($L$2="","",EOMONTH(Z16,0))) | AC16: =IF(P16="","",IF($L$2="","",AB16-Z16)+1) | AD16: =IF(P16="","",IF(DAY(Z16)=1,1,0)) | AE16: =IF(P16="","",IF(B16="お買い上げ型","無",IF(U16<Z16,"無","有"))) | AF16: =IF(P16="","",IF(AE16="無","",DATEDIF(Z16,U16,"y"))) | AG16: =IF(P16="","",IF(AE16="無","",IF(YEAR(U16)&MONTH(U16)=YEAR(Z16)&MONTH(Z16),0,DATEDIF(Z16,U16,"m")-(12*AF16)+Y16+AD16-IF((DAY(Z16)-DAY(U16))<=0,1,0)))) | AH16: =IF(P16="","",IF(AE16="無","",IF(YEAR(U16)&MONTH(U16)=YEAR(Z16)&MONTH(Z16),AC16,IF(V16=X16,0,X16)+IF(AA16=AC16,0,AC16)))) | AI16: =IF(P16="","",AF16&"年"&AG16&"か月"&AH16&"日") | AJ16: =IF(P16="","",IF(AE16="無",0,IF(YEAR(U16)&MONTH(U16)=YEAR(Z16)&MONTH(Z16),ROUNDDOWN(C16*AH16/V16,0),ROUNDDOWN(C16*IF(V16=X16,0,X16)/V16,0)+ROUNDDOWN(C16*IF(AA16=AC16,0,AC16)/AA16,0)))) | AK16: =IF(P16="","",IF(AE16="無",0,ROUNDDOWN((C16*AG16)+(C16*AF16*12),0))) | AL16: =IF(P16="","",AJ16+AK16) | AM16: =IF(P16="","",IF(COUNTIF(B16,"LAN*")=1,AJ16+AK16,IF(AJ16+AK16>=10000,10000,AJ16+AK16))) | AR16: 10 | AS16: 10 | AT16: 10
AR17: 11 | AS17: 11 | AT17: 11
A18: 5 | B18: プラン | E18: 利用開始日 | L18: 台数 | N18: 違約金 | P18: 利用開始 | Q18: 歴日数 | R18: EOM | S18: 日割数 | T18: 満フラグ | U18: 満了日 | V18: 歴日数 | W18: EOM | X18: 日割数 | Y18: 満フラグ | Z18: 解約日 | AA18: 歴日数 | AB18: EOM | AC18: 日割数 | AD18: 満フラグ | AE18: 違約金有無 | AF18: 残期間(年) | AG18: 残期間(月) | AH18: 残期間(日) | AI18: 残期間 | AJ18: 解約金日割 | AK18: 満額 | AL18: 違約金計 | AM18: 違約金表示 | AR18: 12 | AS18: 12 | AT18: 12
C19: =IF(B19="","",VLOOKUP(B19,$AO$7:$AP$12,2,)) | F19: 年 | H19: 月 | J19: 日 | N19: =IF(OR(L19="",AM19=""),"",AM19*L19) | P19: =IF(OR(E19="",G19="",I19=""),"",DATE(E19,G19,I19)) | Q19: =IF(P19="","",IF(OR(G19=1,G19=3,G19=5,G19=7,G19=8,G19=10,G19=12),31,IF(OR(G19=4,G19=6,G19=9,G19=11),30,IF(AND(E19=2020,G19=2),29,IF(AND(E19=2024,G19=2),29,28))))) | R19: =IF(P19="","",EOMONTH(P19,0)) | S19: =IF(P19="","",R19-P19+1) | T19: =IF(P19="","",IF(I19=1,1,0)) | U19: =IF(P19="","",IF(B19="LAN給電5年",DATE(YEAR(P19)+5,MONTH(P19),DAY(P19)-1),DATE(YEAR(P19)+2,MONTH(P19),DAY(P19)-1))) | V19: =IF(P19="","",IF(OR(MONTH(U19)=1,MONTH(U19)=3,MONTH(U19)=5,MONTH(U19)=7,MONTH(U19)=8,MONTH(U19)=10,MONTH(U19)=12),31,IF(OR(MONTH(U19)=4,MONTH(U19)=6,MONTH(U19)=9,MONTH(U19)=11),30,IF(AND(YEAR(U19)=2020,MONTH(U19)=2),29,IF(AND(YEAR(U19)=2024,MONTH(U19)=2),29,28))))) | W19: =IF(P19="","",EOMONTH(U19,-1)+1) | X19: =IF(P19="","",U19-W19+1) | Y19: =IF(P19="","",IF(U19=EOMONTH(U19,0),1,0)) | Z19: =IF(P19="","",IF($L$2="","",$L$2)) | AA19: =IF(P19="","",IF(OR(MONTH(Z19)=1,MONTH(Z19)=3,MONTH(Z19)=5,MONTH(Z19)=7,MONTH(Z19)=8,MONTH(Z19)=10,MONTH(Z19)=12),31,IF(OR(MONTH(Z19)=4,MONTH(Z19)=6,MONTH(Z19)=9,MONTH(Z19)=11),30,IF(AND(YEAR(Z19)=2020,MONTH(Z19)=2),29,IF(AND(YEAR(Z19)=2024,MONTH(Z19)=2),29,28))))) | AB19: =IF(P19="","",IF($L$2="","",EOMONTH(Z19,0))) | AC19: =IF(P19="","",IF($L$2="","",AB19-Z19)+1) | AD19: =IF(P19="","",IF(DAY(Z19)=1,1,0)) | AE19: =IF(P19="","",IF(B19="お買い上げ型","無",IF(U19<Z19,"無","有"))) | AF19: =IF(P19="","",IF(AE19="無","",DATEDIF(Z19,U19,"y"))) | AG19: =IF(P19="","",IF(AE19="無","",IF(YEAR(U19)&MONTH(U19)=YEAR(Z19)&MONTH(Z19),0,DATEDIF(Z19,U19,"m")-(12*AF19)+Y19+AD19-IF((DAY(Z19)-DAY(U19))<=0,1,0)))) | AH19: =IF(P19="","",IF(AE19="無","",IF(YEAR(U19)&MONTH(U19)=YEAR(Z19)&MONTH(Z19),AC19,IF(V19=X19,0,X19)+IF(AA19=AC19,0,AC19)))) | AI19: =IF(P19="","",AF19&"年"&AG19&"か月"&AH19&"日") | AJ19: =IF(P19="","",IF(AE19="無",0,IF(YEAR(U19)&MONTH(U19)=YEAR(Z19)&MONTH(Z19),ROUNDDOWN(C19*AH19/V19,0),ROUNDDOWN(C19*IF(V19=X19,0,X19)/V19,0)+ROUNDDOWN(C19*IF(AA19=AC19,0,AC19)/AA19,0)))) | AK19: =IF(P19="","",IF(AE19="無",0,ROUNDDOWN((C19*AG19)+(C19*AF19*12),0))) | AL19: =IF(P19="","",AJ19+AK19) | AM19: =IF(P19="","",IF(COUNTIF(B19,"LAN*")=1,AJ19+AK19,IF(AJ19+AK19>=10000,10000,AJ19+AK19))) | AS19: 13 | AT19: 13
AS20: 14 | AT20: 14
A21: 6 | B21: プラン | E21: 利用開始日 | L21: 台数 | N21: 違約金 | P21: 利用開始 | Q21: 歴日数 | R21: EOM | S21: 日割数 | T21: 満フラグ | U21: 満了日 | V21: 歴日数 | W21: EOM | X21: 日割数 | Y21: 満フラグ | Z21: 解約日 | AA21: 歴日数 | AB21: EOM | AC21: 日割数 | AD21: 満フラグ | AE21: 違約金有無 | AF21: 残期間(年) | AG21: 残期間(月) | AH21: 残期間(日) | AI21: 残期間 | AJ21: 解約金日割 | AK21: 満額 | AL21: 違約金計 | AM21: 違約金表示 | AS21: 15 | AT21: 15
C22: =IF(B22="","",VLOOKUP(B22,$AO$7:$AP$12,2,)) | F22: 年 | H22: 月 | J22: 日 | N22: =IF(OR(L22="",AM22=""),"",AM22*L22) | P22: =IF(OR(E22="",G22="",I22=""),"",DATE(E22,G22,I22)) | Q22: =IF(P22="","",IF(OR(G22=1,G22=3,G22=5,G22=7,G22=8,G22=10,G22=12),31,IF(OR(G22=4,G22=6,G22=9,G22=11),30,IF(AND(E22=2020,G22=2),29,IF(AND(E22=2024,G22=2),29,28))))) | R22: =IF(P22="","",EOMONTH(P22,0)) | S22: =IF(P22="","",R22-P22+1) | T22: =IF(P22="","",IF(I22=1,1,0)) | U22: =IF(P22="","",IF(B22="LAN給電5年",DATE(YEAR(P22)+5,MONTH(P22),DAY(P22)-1),DATE(YEAR(P22)+2,MONTH(P22),DAY(P22)-1))) | V22: =IF(P22="","",IF(OR(MONTH(U22)=1,MONTH(U22)=3,MONTH(U22)=5,MONTH(U22)=7,MONTH(U22)=8,MONTH(U22)=10,MONTH(U22)=12),31,IF(OR(MONTH(U22)=4,MONTH(U22)=6,MONTH(U22)=9,MONTH(U22)=11),30,IF(AND(YEAR(U22)=2020,MONTH(U22)=2),29,IF(AND(YEAR(U22)=2024,MONTH(U22)=2),29,28))))) | W22: =IF(P22="","",EOMONTH(U22,-1)+1) | X22: =IF(P22="","",U22-W22+1) | Y22: =IF(P22="","",IF(U22=EOMONTH(U22,0),1,0)) | Z22: =IF(P22="","",IF($L$2="","",$L$2)) | AA22: =IF(P22="","",IF(OR(MONTH(Z22)=1,MONTH(Z22)=3,MONTH(Z22)=5,MONTH(Z22)=7,MONTH(Z22)=8,MONTH(Z22)=10,MONTH(Z22)=12),31,IF(OR(MONTH(Z22)=4,MONTH(Z22)=6,MONTH(Z22)=9,MONTH(Z22)=11),30,IF(AND(YEAR(Z22)=2020,MONTH(Z22)=2),29,IF(AND(YEAR(Z22)=2024,MONTH(Z22)=2),29,28))))) | AB22: =IF(P22="","",IF($L$2="","",EOMONTH(Z22,0))) | AC22: =IF(P22="","",IF($L$2="","",AB22-Z22)+1) | AD22: =IF(P22="","",IF(DAY(Z22)=1,1,0)) | AE22: =IF(P22="","",IF(B22="お買い上げ型","無",IF(U22<Z22,"無","有"))) | AF22: =IF(P22="","",IF(AE22="無","",DATEDIF(Z22,U22,"y"))) | AG22: =IF(P22="","",IF(AE22="無","",IF(YEAR(U22)&MONTH(U22)=YEAR(Z22)&MONTH(Z22),0,DATEDIF(Z22,U22,"m")-(12*AF22)+Y22+AD22-IF((DAY(Z22)-DAY(U22))<=0,1,0)))) | AH22: =IF(P22="","",IF(AE22="無","",IF(YEAR(U22)&MONTH(U22)=YEAR(Z22)&MONTH(Z22),AC22,IF(V22=X22,0,X22)+IF(AA22=AC22,0,AC22)))) | AI22: =IF(P22="","",AF22&"年"&AG22&"か月"&AH22&"日") | AJ22: =IF(P22="","",IF(AE22="無",0,IF(YEAR(U22)&MONTH(U22)=YEAR(Z22)&MONTH(Z22),ROUNDDOWN(C22*AH22/V22,0),ROUNDDOWN(C22*IF(V22=X22,0,X22)/V22,0)+ROUNDDOWN(C22*IF(AA22=AC22,0,AC22)/AA22,0)))) | AK22: =IF(P22="","",IF(AE22="無",0,ROUNDDOWN((C22*AG22)+(C22*AF22*12),0))) | AL22: =IF(P22="","",AJ22+AK22) | AM22: =IF(P22="","",IF(COUNTIF(B22,"LAN*")=1,AJ22+AK22,IF(AJ22+AK22>=10000,10000,AJ22+AK22))) | AS22: 16 | AT22: 16
AS23: 17 | AT23: 17
A24: 7 | B24: プラン | E24: 利用開始日 | L24: 台数 | N24: 違約金 | P24: 利用開始 | Q24: 歴日数 | R24: EOM | S24: 日割数 | T24: 満フラグ | U24: 満了日 | V24: 歴日数 | W24: EOM | X24: 日割数 | Y24: 満フラグ | Z24: 解約日 | AA24: 歴日数 | AB24: EOM | AC24: 日割数 | AD24: 満フラグ | AE24: 違約金有無 | AF24: 残期間(年) | AG24: 残期間(月) | AH24: 残期間(日) | AI24: 残期間 | AJ24: 解約金日割 | AK24: 満額 | AL24: 違約金計 | AM24: 違約金表示 | AS24: 18 | AT24: 18
C25: =IF(B25="","",VLOOKUP(B25,$AO$7:$AP$12,2,)) | F25: 年 | H25: 月 | J25: 日 | N25: =IF(OR(L25="",AM25=""),"",AM25*L25) | P25: =IF(OR(E25="",G25="",I25=""),"",DATE(E25,G25,I25)) | Q25: =IF(P25="","",IF(OR(G25=1,G25=3,G25=5,G25=7,G25=8,G25=10,G25=12),31,IF(OR(G25=4,G25=6,G25=9,G25=11),30,IF(AND(E25=2020,G25=2),29,IF(AND(E25=2024,G25=2),29,28))))) | R25: =IF(P25="","",EOMONTH(P25,0)) | S25: =IF(P25="","",R25-P25+1) | T25: =IF(P25="","",IF(I25=1,1,0)) | U25: =IF(P25="","",IF(B25="LAN給電5年",DATE(YEAR(P25)+5,MONTH(P25),DAY(P25)-1),DATE(YEAR(P25)+2,MONTH(P25),DAY(P25)-1))) | V25: =IF(P25="","",IF(OR(MONTH(U25)=1,MONTH(U25)=3,MONTH(U25)=5,MONTH(U25)=7,MONTH(U25)=8,MONTH(U25)=10,MONTH(U25)=12),31,IF(OR(MONTH(U25)=4,MONTH(U25)=6,MONTH(U25)=9,MONTH(U25)=11),30,IF(AND(YEAR(U25)=2020,MONTH(U25)=2),29,IF(AND(YEAR(U25)=2024,MONTH(U25)=2),29,28))))) | W25: =IF(P25="","",EOMONTH(U25,-1)+1) | X25: =IF(P25="","",U25-W25+1) | Y25: =IF(P25="","",IF(U25=EOMONTH(U25,0),1,0)) | Z25: =IF(P25="","",IF($L$2="","",$L$2)) | AA25: =IF(P25="","",IF(OR(MONTH(Z25)=1,MONTH(Z25)=3,MONTH(Z25)=5,MONTH(Z25)=7,MONTH(Z25)=8,MONTH(Z25)=10,MONTH(Z25)=12),31,IF(OR(MONTH(Z25)=4,MONTH(Z25)=6,MONTH(Z25)=9,MONTH(Z25)=11),30,IF(AND(YEAR(Z25)=2020,MONTH(Z25)=2),29,IF(AND(YEAR(Z25)=2024,MONTH(Z25)=2),29,28))))) | AB25: =IF(P25="","",IF($L$2="","",EOMONTH(Z25,0))) | AC25: =IF(P25="","",IF($L$2="","",AB25-Z25)+1) | AD25: =IF(P25="","",IF(DAY(Z25)=1,1,0)) | AE25: =IF(P25="","",IF(B25="お買い上げ型","無",IF(U25<Z25,"無","有"))) | AF25: =IF(P25="","",IF(AE25="無","",DATEDIF(Z25,U25,"y"))) | AG25: =IF(P25="","",IF(AE25="無","",IF(YEAR(U25)&MONTH(U25)=YEAR(Z25)&MONTH(Z25),0,DATEDIF(Z25,U25,"m")-(12*AF25)+Y25+AD25-IF((DAY(Z25)-DAY(U25))<=0,1,0)))) | AH25: =IF(P25="","",IF(AE25="無","",IF(YEAR(U25)&MONTH(U25)=YEAR(Z25)&MONTH(Z25),AC25,IF(V25=X25,0,X25)+IF(AA25=AC25,0,AC25)))) | AI25: =IF(P25="","",AF25&"年"&AG25&"か月"&AH25&"日") | AJ25: =IF(P25="","",IF(AE25="無",0,IF(YEAR(U25)&MONTH(U25)=YEAR(Z25)&MONTH(Z25),ROUNDDOWN(C25*AH25/V25,0),ROUNDDOWN(C25*IF(V25=X25,0,X25)/V25,0)+ROUNDDOWN(C25*IF(AA25=AC25,0,AC25)/AA25,0)))) | AK25: =IF(P25="","",IF(AE25="無",0,ROUNDDOWN((C25*AG25)+(C25*AF25*12),0))) | AL25: =IF(P25="","",AJ25+AK25) | AM25: =IF(P25="","",IF(COUNTIF(B25,"LAN*")=1,AJ25+AK25,IF(AJ25+AK25>=10000,10000,AJ25+AK25))) | AS25: 19 | AT25: 19
AS26: 20 | AT26: 20 | AY26: この場合、解約金は34,406円です。
A27: 8 | B27: プラン | E27: 利用開始日 | L27: 台数 | N27: 違約金 | P27: 利用開始 | Q27: 歴日数 | R27: EOM | S27: 日割数 | T27: 満フラグ | U27: 満了日 | V27: 歴日数 | W27: EOM | X27: 日割数 | Y27: 満フラグ | Z27: 解約日 | AA27: 歴日数 | AB27: EOM | AC27: 日割数 | AD27: 満フラグ | AE27: 違約金有無 | AF27: 残期間(年) | AG27: 残期間(月) | AH27: 残期間(日) | AI27: 残期間 | AJ27: 解約金日割 | AK27: 満額 | AL27: 違約金計 | AM27: 違約金表示 | AS27: 21 | AT27: 21 | AY27: 別紙①にも自動的に計算された金額が反映します。
C28: =IF(B28="","",VLOOKUP(B28,$AO$7:$AP$12,2,)) | F28: 年 | H28: 月 | J28: 日 | N28: =IF(OR(L28="",AM28=""),"",AM28*L28) | P28: =IF(OR(E28="",G28="",I28=""),"",DATE(E28,G28,I28)) | Q28: =IF(P28="","",IF(OR(G28=1,G28=3,G28=5,G28=7,G28=8,G28=10,G28=12),31,IF(OR(G28=4,G28=6,G28=9,G28=11),30,IF(AND(E28=2020,G28=2),29,IF(AND(E28=2024,G28=2),29,28))))) | R28: =IF(P28="","",EOMONTH(P28,0)) | S28: =IF(P28="","",R28-P28+1) | T28: =IF(P28="","",IF(I28=1,1,0)) | U28: =IF(P28="","",IF(B28="LAN給電5年",DATE(YEAR(P28)+5,MONTH(P28),DAY(P28)-1),DATE(YEAR(P28)+2,MONTH(P28),DAY(P28)-1))) | V28: =IF(P28="","",IF(OR(MONTH(U28)=1,MONTH(U28)=3,MONTH(U28)=5,MONTH(U28)=7,MONTH(U28)=8,MONTH(U28)=10,MONTH(U28)=12),31,IF(OR(MONTH(U28)=4,MONTH(U28)=6,MONTH(U28)=9,MONTH(U28)=11),30,IF(AND(YEAR(U28)=2020,MONTH(U28)=2),29,IF(AND(YEAR(U28)=2024,MONTH(U28)=2),29,28))))) | W28: =IF(P28="","",EOMONTH(U28,-1)+1) | X28: =IF(P28="","",U28-W28+1) | Y28: =IF(P28="","",IF(U28=EOMONTH(U28,0),1,0)) | Z28: =IF(P28="","",IF($L$2="","",$L$2)) | AA28: =IF(P28="","",IF(OR(MONTH(Z28)=1,MONTH(Z28)=3,MONTH(Z28)=5,MONTH(Z28)=7,MONTH(Z28)=8,MONTH(Z28)=10,MONTH(Z28)=12),31,IF(OR(MONTH(Z28)=4,MONTH(Z28)=6,MONTH(Z28)=9,MONTH(Z28)=11),30,IF(AND(YEAR(Z28)=2020,MONTH(Z28)=2),29,IF(AND(YEAR(Z28)=2024,MONTH(Z28)=2),29,28))))) | AB28: =IF(P28="","",IF($L$2="","",EOMONTH(Z28,0))) | AC28: =IF(P28="","",IF($L$2="","",AB28-Z28)+1) | AD28: =IF(P28="","",IF(DAY(Z28)=1,1,0)) | AE28: =IF(P28="","",IF(B28="お買い上げ型","無",IF(U28<Z28,"無","有"))) | AF28: =IF(P28="","",IF(AE28="無","",DATEDIF(Z28,U28,"y"))) | AG28: =IF(P28="","",IF(AE28="無","",IF(YEAR(U28)&MONTH(U28)=YEAR(Z28)&MONTH(Z28),0,DATEDIF(Z28,U28,"m")-(12*AF28)+Y28+AD28-IF((DAY(Z28)-DAY(U28))<=0,1,0)))) | AH28: =IF(P28="","",IF(AE28="無","",IF(YEAR(U28)&MONTH(U28)=YEAR(Z28)&MONTH(Z28),AC28,IF(V28=X28,0,X28)+IF(AA28=AC28,0,AC28)))) | AI28: =IF(P28="","",AF28&"年"&AG28&"か月"&AH28&"日") | AJ28: =IF(P28="","",IF(AE28="無",0,IF(YEAR(U28)&MONTH(U28)=YEAR(Z28)&MONTH(Z28),ROUNDDOWN(C28*AH28/V28,0),ROUNDDOWN(C28*IF(V28=X28,0,X28)/V28,0)+ROUNDDOWN(C28*IF(AA28=AC28,0,AC28)/AA28,0)))) | AK28: =IF(P28="","",IF(AE28="無",0,ROUNDDOWN((C28*AG28)+(C28*AF28*12),0))) | AL28: =IF(P28="","",AJ28+AK28) | AM28: =IF(P28="","",IF(COUNTIF(B28,"LAN*")=1,AJ28+AK28,IF(AJ28+AK28>=10000,10000,AJ28+AK28))) | AS28: 22 | AT28: 22
AS29: 23 | AT29: 23
A30: 9 | B30: プラン | E30: 利用開始日 | L30: 台数 | N30: 違約金 | P30: 利用開始 | Q30: 歴日数 | R30: EOM | S30: 日割数 | T30: 満フラグ | U30: 満了日 | V30: 歴日数 | W30: EOM | X30: 日割数 | Y30: 満フラグ | Z30: 解約日 | AA30: 歴日数 | AB30: EOM | AC30: 日割数 | AD30: 満フラグ | AE30: 違約金有無 | AF30: 残期間(年) | AG30: 残期間(月) | AH30: 残期間(日) | AI30: 残期間 | AJ30: 解約金日割 | AK30: 満額 | AL30: 違約金計 | AM30: 違約金表示 | AS30: 24 | AT30: 24
C31: =IF(B31="","",VLOOKUP(B31,$AO$7:$AP$12,2,)) | F31: 年 | H31: 月 | J31: 日 | N31: =IF(OR(L31="",AM31=""),"",AM31*L31) | P31: =IF(OR(E31="",G31="",I31=""),"",DATE(E31,G31,I31)) | Q31: =IF(P31="","",IF(OR(G31=1,G31=3,G31=5,G31=7,G31=8,G31=10,G31=12),31,IF(OR(G31=4,G31=6,G31=9,G31=11),30,IF(AND(E31=2020,G31=2),29,IF(AND(E31=2024,G31=2),29,28))))) | R31: =IF(P31="","",EOMONTH(P31,0)) | S31: =IF(P31="","",R31-P31+1) | T31: =IF(P31="","",IF(I31=1,1,0)) | U31: =IF(P31="","",IF(B31="LAN給電5年",DATE(YEAR(P31)+5,MONTH(P31),DAY(P31)-1),DATE(YEAR(P31)+2,MONTH(P31),DAY(P31)-1))) | V31: =IF(P31="","",IF(OR(MONTH(U31)=1,MONTH(U31)=3,MONTH(U31)=5,MONTH(U31)=7,MONTH(U31)=8,MONTH(U31)=10,MONTH(U31)=12),31,IF(OR(MONTH(U31)=4,MONTH(U31)=6,MONTH(U31)=9,MONTH(U31)=11),30,IF(AND(YEAR(U31)=2020,MONTH(U31)=2),29,IF(AND(YEAR(U31)=2024,MONTH(U31)=2),29,28))))) | W31: =IF(P31="","",EOMONTH(U31,-1)+1) | X31: =IF(P31="","",U31-W31+1) | Y31: =IF(P31="","",IF(U31=EOMONTH(U31,0),1,0)) | Z31: =IF(P31="","",IF($L$2="","",$L$2)) | AA31: =IF(P31="","",IF(OR(MONTH(Z31)=1,MONTH(Z31)=3,MONTH(Z31)=5,MONTH(Z31)=7,MONTH(Z31)=8,MONTH(Z31)=10,MONTH(Z31)=12),31,IF(OR(MONTH(Z31)=4,MONTH(Z31)=6,MONTH(Z31)=9,MONTH(Z31)=11),30,IF(AND(YEAR(Z31)=2020,MONTH(Z31)=2),29,IF(AND(YEAR(Z31)=2024,MONTH(Z31)=2),29,28))))) | AB31: =IF(P31="","",IF($L$2="","",EOMONTH(Z31,0))) | AC31: =IF(P31="","",IF($L$2="","",AB31-Z31)+1) | AD31: =IF(P31="","",IF(DAY(Z31)=1,1,0)) | AE31: =IF(P31="","",IF(B31="お買い上げ型","無",IF(U31<Z31,"無","有"))) | AF31: =IF(P31="","",IF(AE31="無","",DATEDIF(Z31,U31,"y"))) | AG31: =IF(P31="","",IF(AE31="無","",IF(YEAR(U31)&MONTH(U31)=YEAR(Z31)&MONTH(Z31),0,DATEDIF(Z31,U31,"m")-(12*AF31)+Y31+AD31-IF((DAY(Z31)-DAY(U31))<=0,1,0)))) | AH31: =IF(P31="","",IF(AE31="無","",IF(YEAR(U31)&MONTH(U31)=YEAR(Z31)&MONTH(Z31),AC31,IF(V31=X31,0,X31)+IF(AA31=AC31,0,AC31)))) | AI31: =IF(P31="","",AF31&"年"&AG31&"か月"&AH31&"日") | AJ31: =IF(P31="","",IF(AE31="無",0,IF(YEAR(U31)&MONTH(U31)=YEAR(Z31)&MONTH(Z31),ROUNDDOWN(C31*AH31/V31,0),ROUNDDOWN(C31*IF(V31=X31,0,X31)/V31,0)+ROUNDDOWN(C31*IF(AA31=AC31,0,AC31)/AA31,0)))) | AK31: =IF(P31="","",IF(AE31="無",0,ROUNDDOWN((C31*AG31)+(C31*AF31*12),0))) | AL31: =IF(P31="","",AJ31+AK31) | AM31: =IF(P31="","",IF(COUNTIF(B31,"LAN*")=1,AJ31+AK31,IF(AJ31+AK31>=10000,10000,AJ31+AK31))) | AS31: 25 | AT31: 25
AS32: 26 | AT32: 26
A33: 10 | B33: プラン | E33: 利用開始日 | L33: 台数 | N33: 違約金 | P33: 利用開始 | Q33: 歴日数 | R33: EOM | S33: 日割数 | T33: 満フラグ | U33: 満了日 | V33: 歴日数 | W33: EOM | X33: 日割数 | Y33: 満フラグ | Z33: 解約日 | AA33: 歴日数 | AB33: EOM | AC33: 日割数 | AD33: 満フラグ | AE33: 違約金有無 | AF33: 残期間(年) | AG33: 残期間(月) | AH33: 残期間(日) | AI33: 残期間 | AJ33: 解約金日割 | AK33: 満額 | AL33: 違約金計 | AM33: 違約金表示 | AS33: 27 | AT33: 27
C34: =IF(B34="","",VLOOKUP(B34,$AO$7:$AP$12,2,)) | F34: 年 | H34: 月 | J34: 日 | N34: =IF(OR(L34="",AM34=""),"",AM34*L34) | P34: =IF(OR(E34="",G34="",I34=""),"",DATE(E34,G34,I34)) | Q34: =IF(P34="","",IF(OR(G34=1,G34=3,G34=5,G34=7,G34=8,G34=10,G34=12),31,IF(OR(G34=4,G34=6,G34=9,G34=11),30,IF(AND(E34=2020,G34=2),29,IF(AND(E34=2024,G34=2),29,28))))) | R34: =IF(P34="","",EOMONTH(P34,0)) | S34: =IF(P34="","",R34-P34+1) | T34: =IF(P34="","",IF(I34=1,1,0)) | U34: =IF(P34="","",IF(B34="LAN給電5年",DATE(YEAR(P34)+5,MONTH(P34),DAY(P34)-1),DATE(YEAR(P34)+2,MONTH(P34),DAY(P34)-1))) | V34: =IF(P34="","",IF(OR(MONTH(U34)=1,MONTH(U34)=3,MONTH(U34)=5,MONTH(U34)=7,MONTH(U34)=8,MONTH(U34)=10,MONTH(U34)=12),31,IF(OR(MONTH(U34)=4,MONTH(U34)=6,MONTH(U34)=9,MONTH(U34)=11),30,IF(AND(YEAR(U34)=2020,MONTH(U34)=2),29,IF(AND(YEAR(U34)=2024,MONTH(U34)=2),29,28))))) | W34: =IF(P34="","",EOMONTH(U34,-1)+1) | X34: =IF(P34="","",U34-W34+1) | Y34: =IF(P34="","",IF(U34=EOMONTH(U34,0),1,0)) | Z34: =IF(P34="","",IF($L$2="","",$L$2)) | AA34: =IF(P34="","",IF(OR(MONTH(Z34)=1,MONTH(Z34)=3,MONTH(Z34)=5,MONTH(Z34)=7,MONTH(Z34)=8,MONTH(Z34)=10,MONTH(Z34)=12),31,IF(OR(MONTH(Z34)=4,MONTH(Z34)=6,MONTH(Z34)=9,MONTH(Z34)=11),30,IF(AND(YEAR(Z34)=2020,MONTH(Z34)=2),29,IF(AND(YEAR(Z34)=2024,MONTH(Z34)=2),29,28))))) | AB34: =IF(P34="","",IF($L$2="","",EOMONTH(Z34,0))) | AC34: =IF(P34="","",IF($L$2="","",AB34-Z34)+1) | AD34: =IF(P34="","",IF(DAY(Z34)=1,1,0)) | AE34: =IF(P34="","",IF(B34="お買い上げ型","無",IF(U34<Z34,"無","有"))) | AF34: =IF(P34="","",IF(AE34="無","",DATEDIF(Z34,U34,"y"))) | AG34: =IF(P34="","",IF(AE34="無","",IF(YEAR(U34)&MONTH(U34)=YEAR(Z34)&MONTH(Z34),0,DATEDIF(Z34,U34,"m")-(12*AF34)+Y34+AD34-IF((DAY(Z34)-DAY(U34))<=0,1,0)))) | AH34: =IF(P34="","",IF(AE34="無","",IF(YEAR(U34)&MONTH(U34)=YEAR(Z34)&MONTH(Z34),AC34,IF(V34=X34,0,X34)+IF(AA34=AC34,0,AC34)))) | AI34: =IF(P34="","",AF34&"年"&AG34&"か月"&AH34&"日") | AJ34: =IF(P34="","",IF(AE34="無",0,IF(YEAR(U34)&MONTH(U34)=YEAR(Z34)&MONTH(Z34),ROUNDDOWN(C34*AH34/V34,0),ROUNDDOWN(C34*IF(V34=X34,0,X34)/V34,0)+ROUNDDOWN(C34*IF(AA34=AC34,0,AC34)/AA34,0)))) | AK34: =IF(P34="","",IF(AE34="無",0,ROUNDDOWN((C34*AG34)+(C34*AF34*12),0))) | AL34: =IF(P34="","",AJ34+AK34) | AM34: =IF(P34="","",IF(COUNTIF(B34,"LAN*")=1,AJ34+AK34,IF(AJ34+AK34>=10000,10000,AJ34+AK34))) | AS34: 28 | AT34: 28
AS35: 29 | AT35: 29
AS36: 30 | AT36: 30
AS37: 31 | AT37: 31
AT38: 32
AT39: 33
AT40: 34
AT41: 35
...
